<?xml version="1.0"?>
<robot name="jerry" xmlns:xacro="http://www.ros.org/wiki/xacro">

    <!-- <xacro:include filename="$(find jerry_bot_description)/urdf/xacro_common_params.xacro"/> -->
    <xacro:macro name="default_origin">
        <origin xyz="0 0 0" rpy="0 0 0"/>
    </xacro:macro>

    <xacro:macro name="default_inertia">
        <inertial>
            <xacro:default_origin />
            <mass value="1.0"/>
            <inertia ixx="0.0036" ixy="0.0" ixz="0.0" iyy="0.0036" iyz="0.0" izz="0.0066"/>
            <!-- <inertia ixx="1.0" ixy="0.0" ixz="0.0" iyy="1.0" iyz="0.0" izz="1.0"/> -->
        </inertial>
    </xacro:macro>

    <link name="base_footprint"/> 
    
    <link name="base_link">
        <xacro:default_inertia />
        <visual name="">
            <origin xyz="0.0 0.0 0.0" rpy="0.0 0.0 0.0"/>
            <geometry>
                <mesh filename="package://jerry_bot_description/meshes/jerry_base.dae"/>
            </geometry>
            <!-- <material name="white"/> -->
        </visual>
        <collision>
            <origin xyz="0.0 0.0 0.112" rpy="0.0 0.0 0.0"/>       
            <geometry>
                <box size="0.13 0.185 0.22"/> 
            </geometry>
        </collision>
    </link>

    <joint name="robot_footprint_joint" type="fixed">
        <origin xyz="0.0 0.0 0.0" rpy="0.0 0.0 0.0"/>
        <parent link="base_footprint"/>
        <child link="base_link" />
    </joint>

    <link name="left_wheel_link">
        <xacro:default_inertia />
        <visual name="">
            <xacro:default_origin />
            <geometry>
                <mesh filename="package://jerry_bot_description/meshes/wheel_blue.dae"/>
            </geometry>
            <!-- <material name="blue"/> -->
        </visual>
        <collision>
            <xacro:default_origin />    
            <geometry>
                <cylinder radius="0.033" length="0.025"/>
            </geometry>
        </collision>
    </link>

    <joint name="left_wheel_joint" type="continuous">
        <origin xyz="0.044 0.1135 0.033" rpy="-1.5708 0.0 0.0"/>
        <parent link="base_link"/>
        <child link="left_wheel_link" />
        <axis xyz="0 0 1"/>
    </joint>

    <link name="right_wheel_link">
        <xacro:default_inertia />
        <visual name="">
            <xacro:default_origin />
            <geometry>
                <mesh filename="package://jerry_bot_description/meshes/wheel_blue.dae"/>
            </geometry>
            <!-- <material name="blue"/> -->
        </visual>
        <collision>
            <xacro:default_origin />    
            <geometry>
                <cylinder radius="0.033" length="0.025"/>
            </geometry>
        </collision>
    </link>

    <joint name="right_wheel_joint" type="continuous">
        <origin xyz="0.044 -0.1135 0.033" rpy="-1.5708 0.0 0.0"/>
        <parent link="base_link"/>
        <child link="right_wheel_link" />
        <axis xyz="0 0 1"/>
    </joint>

    <link name="imu_link"/>

    <joint name="imu_joint" type="fixed">
        <parent link="base_link"/>
        <child link="imu_link"/>
        <origin xyz="0.05 0.06 0.135" rpy="0 0 0"/>
    </joint>

    <link name="camera_link"/>

    <joint name="cam_joint" type="fixed">
        <parent link="base_link"/>
        <child link="camera_link"/>
        <origin xyz="0.05 0.0 0.15" rpy="0 0 0"/>
    </joint>


    <link name="lidar_link"/>

    <joint name="lidar_joint" type="fixed">
        <origin xyz="0.0 0.0 0.22" rpy="0.0 0.0 0.0"/>
        <parent link="base_link"/>
        <child link="lidar_link" />
    </joint>



</robot>